using System.Net;
using System.Net.Http;
using PythonTests;
using System.Net.Http.Headers;
using System.Threading.Tasks;
using Xunit;
namespace PythonTests{
    [TestCaseOrderer("PythonTests.PriorityOrderer", "PythonTests")]
    public class ShipmentTest : BaseTest {
        public ShipmentTest() : base(){}
        [Fact, TestPriority(1)]
        public async Task GetAllShipments()
        {
            var requestUri = "/api/v1/shipments";

            var response = await _client.GetAsync(requestUri);
            var result = await response.Content.ReadAsStringAsync();
            Xunit.Assert.NotNull(result);
            Xunit.Assert.Equal(HttpStatusCode.OK, response.StatusCode);
            Xunit.Assert.Equal("[]", result);
        }
        [Fact, TestPriority(2)]
        public async Task GetOneShipmentBeforeAdding(){
            var requestUri = "/api/v1/shipments/1";
            var response = await _client.GetAsync(requestUri);
            var result = await response.Content.ReadAsStringAsync();
            Xunit.Assert.NotNull(result);
            Xunit.Assert.Equal(HttpStatusCode.OK, response.StatusCode);
            Xunit.Assert.Equal("null", result);
            // It should absolutely be either 400 bad request or 404 not found, but it is 200 OK.
            // This is idiotic.
        }
        [Fact, TestPriority(3)]
        public async Task CreateShipment()
        {
            var requestUri = "/api/v1/shipments";
            var response = await _client.PostAsync(requestUri, new StringContent(""));
            var result = await response.Content.ReadAsStringAsync();
            Xunit.Assert.Equal(HttpStatusCode.Created, response.StatusCode);
        }
        [Fact, TestPriority(4)]
        public async Task GetOneShipmentAfterAdding(){
            var requestUri = "/api/v1/shipments/1";
            var response = await _client.GetAsync(requestUri);
            var result = await response.Content.ReadAsStringAsync();
            Xunit.Assert.NotNull(result);
            Xunit.Assert.Equal(HttpStatusCode.OK, response.StatusCode);
            Xunit.Assert.Contains("",  result);
        }
        [Fact, TestPriority(5)]
        public async Task GetItemsFromShipmentAfterAdding(){
            var requestUri = "/api/v1/shipments/1/items";
            var response = await _client.GetAsync(requestUri);
            var result = await response.Content.ReadAsStringAsync();
            Xunit.Assert.NotNull(result);
            Xunit.Assert.Equal(HttpStatusCode.OK, response.StatusCode);
            Xunit.Assert.Equal("[{\"item_id\": \"P010669\", \"amount\": 16}]", result);
        }
        [Fact, TestPriority(6)]
        public async Task PutShipment(){
            var requestUri = "/api/v1/shipments/1";
            var response = await _client.PutAsync(requestUri, new StringContent(""));
            var result = await response.Content.ReadAsStringAsync();
            Xunit.Assert.Equal(HttpStatusCode.OK, response.StatusCode);
        }
        [Fact, TestPriority(7)]
        public async Task GetOneShipmentAfterPutting(){
            var requestUri = "/api/v1/shipments/1";
            var response = await _client.GetAsync(requestUri);
            var result = await response.Content.ReadAsStringAsync();
            Xunit.Assert.NotNull(result);
            Xunit.Assert.Equal(HttpStatusCode.OK, response.StatusCode);
            Xunit.Assert.Contains("",  result);
        }
        
        [Fact, TestPriority(8)]
        public async Task PutShipmentItems(){
            var requestUri = "/api/v1/shipments/1/items";
            var response = await _client.PutAsync(requestUri, new StringContent(""));
            var result = await response.Content.ReadAsStringAsync();
            Xunit.Assert.Equal(HttpStatusCode.OK, response.StatusCode);
            // Gives Internal Server Error, is because it is updating the Inventories in which the item resides.
            // Because I turned on debug within the python code, the inventories do not exist.
            // Makes sense, but it is not the expected behavior.
        }
        [Fact, TestPriority(9)]
        public async Task GetItemsFromShipmentAfterPutting(){
            var requestUri = "/api/v1/shipments/1/items";
            var response = await _client.GetAsync(requestUri);
            var result = await response.Content.ReadAsStringAsync();
            Xunit.Assert.NotNull(result);
            Xunit.Assert.Equal(HttpStatusCode.OK, response.StatusCode);
            Xunit.Assert.Equal("", result);
        }
        [Fact, TestPriority(10)]
        public async Task DeleteShipment(){
            var requestUri = "/api/v1/shipments/1";
            var response = await _client.DeleteAsync(requestUri);
            var result = await response.Content.ReadAsStringAsync();
            Xunit.Assert.Equal(HttpStatusCode.OK, response.StatusCode);
        }
        [Fact, TestPriority(11)]
        public async Task GetOneShipmentAfterDelete(){
            var requestUri = "/api/v1/shipments/1";
            var response = await _client.GetAsync(requestUri);
            var result = await response.Content.ReadAsStringAsync();
            Xunit.Assert.NotNull(result);
            Xunit.Assert.Equal(HttpStatusCode.OK, response.StatusCode);
            Xunit.Assert.Equal("null", result);
            // It should absolutely be either 400 bad request or 404 not found, but it is 200 OK.
            // This is idiotic.
        }
        [Fact, TestPriority(12)]
        public async Task GetAllShipmentsAfterDelete()
        {
            var requestUri = "/api/v1/shipments";
            var response = await _client.GetAsync(requestUri);
            var result = await response.Content.ReadAsStringAsync();
            Xunit.Assert.NotNull(result);
            Xunit.Assert.Equal(HttpStatusCode.OK, response.StatusCode);
            Xunit.Assert.Equal("[]", result);
        }
    }
}